<?xml version="1.0" ?>
<!-- =================================================================================== -->
<!-- |    This document was autogenerated by xacro from lynxmotion.urdf.xacro          | -->
<!-- |    EDITING THIS FILE BY HAND IS NOT RECOMMENDED                                 | -->
<!-- =================================================================================== -->
<robot name="test_robot" xmlns:xacro="http://ros.org/wiki/xacro">
  <!--LINKS -->
  <!-- Link-->
  <link name="base_link">
    <visual>
      <geometry>
        <cylinder length="0.1" radius="0.15"/>
      </geometry>
      <origin_container>
        <origin xyz="0 0 0"/>
      </origin_container>
      <material name="">
        <color rgba="0.1882353 0.1960784 0.2039216 1"/>
      </material>
    </visual>
  </link>
  <!-- Link-->
  <link name="link1">
    <visual>
      <geometry>
        <box size="0 0 0 "/>
      </geometry>
      <origin_container>
        <origin xyz="0 0 0"/>
      </origin_container>
      <material name="">
        <color rgba="0.1882353 0.1960784 0.2039216 1"/>
      </material>
    </visual>
  </link>
  <!-- Link-->
  <link name="link2">
    <visual>
      <geometry>
        <box size=".15 .060325 0.2"/>
      </geometry>
      <origin_container>
        <origin xyz="0 0 0"/>
      </origin_container>
      <material name="">
        <color rgba="0.1882353 0.1960784 0.2039216 1"/>
      </material>
    </visual>
  </link>
  <!-- Link-->
  <link name="link3">
    <visual>
      <geometry>
        <box size="0.01 .1 .2"/>
      </geometry>
      <origin_container>
        <origin xyz="0 0 0"/>
      </origin_container>
      <material name="">
        <color rgba="0.1882353 0.1960784 0.2039216 1"/>
      </material>
    </visual>
  </link>
  <!-- Link-->
  <link name="link8">
    <visual>
      <geometry>
        <box size="0.01 .1 .2"/>
      </geometry>
      <origin_container>
        <origin xyz="0 0 0"/>
      </origin_container>
      <material name="">
        <color rgba="0.1882353 0.1960784 0.2039216 1"/>
      </material>
    </visual>
  </link>
  <!-- Link-->
  <link name="link9">
    <visual>
      <geometry>
        <box size="0.01 .1 .17"/>
      </geometry>
      <origin_container>
        <origin xyz="0 0 0"/>
      </origin_container>
      <material name="">
        <color rgba="0.1882353 0.1960784 0.2039216 1"/>
      </material>
    </visual>
  </link>
  <!-- Link-->
  <link name="link10">
    <visual>
      <geometry>
        <box size="0.01 .1 .2"/>
      </geometry>
      <origin_container>
        <origin xyz="0 0 0"/>
      </origin_container>
      <material name="">
        <color rgba="0.1882353 0.1960784 0.2039216 1"/>
      </material>
    </visual>
  </link>
  <!-- Link-->
  <link name="link11">
    <visual>
      <geometry>
        <box size="0.01 .1 .2"/>
      </geometry>
      <origin_container>
        <origin xyz="0 0 0"/>
      </origin_container>
      <material name="">
        <color rgba="0.1882353 0.1960784 0.2039216 1"/>
      </material>
    </visual>
  </link>
  <!-- Link-->
  <link name="link4">
    <visual>
      <geometry>
        <cylinder length="0.2" radius="0.08"/>
      </geometry>
      <origin_container>
        <origin xyz="0 0 0"/>
      </origin_container>
      <material name="">
        <color rgba="0.1882353 0.1960784 0.2039216 1"/>
      </material>
    </visual>
  </link>
  <!-- Link-->
  <link name="link5">
    <visual>
      <geometry>
        <cylinder length="0.3" radius="0.02"/>
      </geometry>
      <origin_container>
        <origin xyz=" 0 0 0"/>
      </origin_container>
      <material name="">
        <color rgba="0.411765 0.411765 0.411765 1"/>
      </material>
    </visual>
  </link>
  <!-- Link-->
  <link name="link6">
    <visual>
      <geometry>
        <box size="0.12 .12 .12"/>
      </geometry>
      <origin_container>
        <origin xyz="0 0 0"/>
      </origin_container>
      <material name="">
        <color rgba="0.1882353 0.1960784 0.2039216 1"/>
      </material>
    </visual>
  </link>
  <!-- HERE I AM STARTING FOR THE JOINT-->
  <!-- joint-->
  <joint name="joint1" type="revolute">
    <limit effort="1" lower="-1.57" upper="1.57" velocity="10"/>
    <axis xyz="0 0 1"/>
    <origin xyz="0 0 0.02"/>
    <parent link="base_link"/>
    <child link="link1"/>
  </joint>
  <!-- joint-->
  <joint name="joint2" type="fixed">
    <origin xyz="0 0 0.05"/>
    <axis xyz="1 0 0"/>
    <parent link="link1"/>
    <child link="link2"/>
  </joint>
  <!-- joint-->
  <joint name="joint3" type="revolute">
    <limit effort="1" lower="-1.57" upper="1.57" velocity="10"/>
    <origin xyz=".08 0 .08"/>
    <axis xyz="1 0 0"/>
    <parent link="link2"/>
    <child link="link3"/>
  </joint>
  <!-- joint-->
  <joint name="joint8" type="fixed">
    <origin xyz="-.16 0 .0"/>
    <axis xyz="1 0 0"/>
    <parent link="link3"/>
    <child link="link8"/>
  </joint>
  <!-- joint-->
  <joint name="joint9" type="fixed">
    <origin rpy="0 1.57075 0" xyz=".08 0 .10"/>
    <axis xyz="0 1 0"/>
    <parent link="link8"/>
    <child link="link9"/>
  </joint>
  <!-- joint-->
  <joint name="joint10" type="fixed">
    <origin xyz=".0 0 .20"/>
    <axis xyz="1 0 0"/>
    <parent link="link8"/>
    <child link="link10"/>
  </joint>
  <!-- joint-->
  <joint name="joint11" type="fixed">
    <origin xyz=".16 0 .20"/>
    <axis xyz="1 0 0"/>
    <parent link="link8"/>
    <child link="link11"/>
  </joint>
  <!-- joint-->
  <joint name="joint4" type="revolute">
    <limit effort="1" lower="-1.57" upper="1.57" velocity="10"/>
    <axis xyz="1 0 0"/>
    <origin rpy="1.57075 0 0" xyz="0.08 0.025 0.300"/>
    <parent link="link8"/>
    <child link="link4"/>
  </joint>
  <!-- joint-->
  <joint name="joint5" type="fixed">
    <origin rpy="0 0 0" xyz="0 0 -0.2"/>
    <axis xyz="0 1 0"/>
    <parent link="link4"/>
    <child link="link5"/>
  </joint>
  <!-- joint-->
  <joint name="joint6" type="revolute">
    <limit effort="1" lower="-3.14" upper="3.14" velocity="10"/>
    <origin rpy="1.57075 0 0" xyz="0 0 -0.2"/>
    <axis xyz="0 1 0"/>
    <parent link="link5"/>
    <child link="link6"/>
  </joint>
</robot>

