<?xml version="1.0" ?>
<!-- =================================================================================== -->
<!-- |    This document was autogenerated by xacro from lynxmotion.urdf.xacro          | -->
<!-- |    EDITING THIS FILE BY HAND IS NOT RECOMMENDED                                 | -->
<!-- =================================================================================== -->
<robot name="test_robot" xmlns:xacro="http://ros.org/wiki/xacro">
  <!-- Conversion were obtained from http://www.e-paint.co.uk/Lab_values.asp
       unless otherwise stated. -->
  <!-- RAL 7032 pebble gray, controller -->
  <!-- RAL 7021 black gray (lynxmotion black) , robot with dark link color -->
  <!--LINKS -->
  <link name="base_link">
    <visual>
      <!-- Geometry-->
      <geometry>
        <cylinder length="0.2" radius="0.2"/>
      </geometry>
      <!-- Origin -->
      <origin_container>
        <origin rpy="0 0 0" xyz="0 0 0"/>
      </origin_container>
      <!-- Material-->
      <material name="">
        <color rgba="0.1882353 0.1960784 0.2039216 1"/>
      </material>
    </visual>
  </link>
  <link name="link1">
    <visual>
      <!-- Geometry-->
      <geometry>
        <box size="0.12 0.05 0.5"/>
      </geometry>
      <!-- Origin -->
      <origin_container>
        <origin rpy="0 0 0" xyz="0 0 0"/>
      </origin_container>
      <!-- Material-->
      <material name="">
        <color rgba="0.1882353 0.1960784 0.2039216 1"/>
      </material>
    </visual>
  </link>
  <link name="link2">
    <visual>
      <!-- Geometry-->
      <geometry>
        <box size="2 0.03 0.3"/>
      </geometry>
      <!-- Origin -->
      <origin_container>
        <origin rpy="0 0 1" xyz="0 0 0"/>
      </origin_container>
      <!-- Material-->
      <material name="">
        <color rgba="0.1882353 0.1960784 0.2039216 1"/>
      </material>
    </visual>
  </link>
  <link name="link3">
    <visual>
      <!-- Geometry-->
      <geometry>
        <box size="0.05 0.05 0.5"/>
      </geometry>
      <!-- Origin -->
      <origin_container>
        <origin rpy="0 0 0" xyz="0 0 0"/>
      </origin_container>
      <!-- Material-->
      <material name="">
        <color rgba="0.1882353 0.1960784 0.2039216 1"/>
      </material>
    </visual>
  </link>
  <link name="link4">
    <visual>
      <!-- Geometry-->
      <geometry>
        <box size="0.05 0.05 0.5"/>
      </geometry>
      <!-- Origin -->
      <origin_container>
        <origin rpy="0 0 0" xyz="0 0 0"/>
      </origin_container>
      <!-- Material-->
      <material name="">
        <color rgba="0.1882353 0.1960784 0.2039216 1"/>
      </material>
    </visual>
  </link>
  <link name="link5">
    <visual>
      <!-- Geometry-->
      <geometry>
        <box size="0.05 0.05 0.5"/>
      </geometry>
      <!-- Origin -->
      <origin_container>
        <origin rpy="0 0 0" xyz="0 0 0"/>
      </origin_container>
      <!-- Material-->
      <material name="">
        <color rgba="0.7058823 0.6901961 0.6313725 1"/>
      </material>
    </visual>
  </link>
  <link name="link6">
    <visual>
      <!-- Geometry-->
      <geometry>
        <box size="0.05 0.05 0.5"/>
      </geometry>
      <!-- Origin -->
      <origin_container>
        <origin rpy="0 0 0" xyz="0 0 0"/>
      </origin_container>
      <!-- Material-->
      <material name="">
        <color rgba="0.1882353 0.1960784 0.2039216 1"/>
      </material>
    </visual>
  </link>
  <!-- HERE I AM STARTING FOR THE JOINT-->
  <joint name="joint1" type="revolute">
    <limit effort="1" lower="-3.14" upper="3.14" velocity="10"/>
    <axis xyz="0 0 1"/>
    <origin xyz="0 0 0.1"/>
    <parent link="base_link"/>
    <child link="link1"/>
  </joint>
  <joint name="joint2" type="revolute">
    <limit effort="1" lower="-1.57" upper="0" velocity="10"/>
    <origin xyz="0.2 0 0"/>
    <axis xyz="1 0 0"/>
    <parent link="link1"/>
    <child link="link2"/>
  </joint>
  <joint name="joint3" type="fixed">
    <origin xyz="0.5 0 0"/>
    <parent link="link2"/>
    <child link="link3"/>
  </joint>
  <joint name="joint4" type="revolute">
    <limit effort="1" lower="-1.57" upper="0" velocity="10"/>
    <axis xyz="1 0 0"/>
    <origin xyz="0 1.5 0"/>
    <parent link="link3"/>
    <child link="link4"/>
  </joint>
  <joint name="joint5" type="fixed">
    <limit effort="1" lower="-1.57" upper="0" velocity="10"/>
    <origin xyz="0 0 0"/>
    <parent link="link4"/>
    <child link="link5"/>
  </joint>
  <joint name="joint6" type="revolute">
    <limit effort="1" lower="-1.57" upper="0" velocity="10"/>
    <origin xyz="0 7.5 0"/>
    <axis xyz="0 0 1"/>
    <parent link="link5"/>
    <child link="link6"/>
  </joint>
</robot>

